Exception in thread Thread-3 (get_all):
Traceback (most recent call last):
  File "/root/sd/buff_test/test.py", line 29, in get_all
    driver.get('https://buff.163.com/goods/' + url)
  File "/usr/local/lib/python3.11/dist-packages/selenium/webdriver/remote/webdriver.py", line 449, in get
    self.execute(Command.GET, {"url": url})
  File "/usr/local/lib/python3.11/dist-packages/selenium/webdriver/remote/webdriver.py", line 440, in execute
    self.error_handler.check_response(response)
  File "/usr/local/lib/python3.11/dist-packages/selenium/webdriver/remote/errorhandler.py", line 245, in check_response
    raise exception_class(message, screen, stacktrace)
selenium.common.exceptions.WebDriverException: Message: unknown error: net::ERR_NAME_NOT_RESOLVED
  (Session info: headless chrome=112.0.5615.49)
Stacktrace:
#0 0x005fb132dbf4 <unknown>
#1 0x005fb1099040 <unknown>
#2 0x005fb10962f8 <unknown>
#3 0x005fb1089734 <unknown>
#4 0x005fb108ab9c <unknown>
#5 0x005fb1089a60 <unknown>
#6 0x005fb1088a9c <unknown>
#7 0x005fb1088968 <unknown>
#8 0x005fb10879bc <unknown>
#9 0x005fb1087c6c <unknown>
#10 0x005fb109af58 <unknown>
#11 0x005fb1102bf4 <unknown>
#12 0x005fb1102544 <unknown>
#13 0x005fb10c4064 <unknown>
#14 0x005fb10c5550 <unknown>
#15 0x005fb1355df4 <unknown>
#16 0x005fb131039c <unknown>
#17 0x005fb130fecc <unknown>
#18 0x005fb13525dc <unknown>
#19 0x005fb1310d78 <unknown>
#20 0x005fb12f44c8 <unknown>
#21 0x005fb131b5e4 <unknown>
#22 0x005fb131b788 <unknown>
#23 0x005fb1325fa0 <unknown>
#24 0x007e09a0edd8 <unknown>
#25 0x007e09a77e5c <unknown>


During handling of the above exception, another exception occurred:

Traceback (most recent call last):
  File "/usr/lib/python3.11/threading.py", line 1038, in _bootstrap_inner
    self.run()
  File "/usr/lib/python3.11/threading.py", line 975, in run
    self._target(*self._args, **self._kwargs)
  File "/root/sd/buff_test/test.py", line 524, in get_all
    send_mail("need to reboot chroot container", 0, '111')
  File "/root/sd/buff_test/test.py", line 578, in send_mail
    server = smtplib.SMTP(smtp_server, smtp_port)
             ^^^^^^^^^^^^^^^^^^^^^^^^^^^^^^^^^^^^
  File "/usr/lib/python3.11/smtplib.py", line 255, in __init__
    (code, msg) = self.connect(host, port)
                  ^^^^^^^^^^^^^^^^^^^^^^^^
  File "/usr/lib/python3.11/smtplib.py", line 341, in connect
    self.sock = self._get_socket(host, port, self.timeout)
                ^^^^^^^^^^^^^^^^^^^^^^^^^^^^^^^^^^^^^^^^^^
  File "/usr/lib/python3.11/smtplib.py", line 312, in _get_socket
    return socket.create_connection((host, port), timeout,
           ^^^^^^^^^^^^^^^^^^^^^^^^^^^^^^^^^^^^^^^^^^^^^^^
  File "/usr/lib/python3.11/socket.py", line 827, in create_connection
    for res in getaddrinfo(host, port, 0, SOCK_STREAM):
               ^^^^^^^^^^^^^^^^^^^^^^^^^^^^^^^^^^^^^^^
  File "/usr/lib/python3.11/socket.py", line 962, in getaddrinfo
    for res in _socket.getaddrinfo(host, port, family, type, proto, flags):
               ^^^^^^^^^^^^^^^^^^^^^^^^^^^^^^^^^^^^^^^^^^^^^^^^^^^^^^^^^^^
socket.gaierror: [Errno -3] Temporary failure in name resolution

Process finished with exit code 0
